  0%|          | 0/4 [00:00<?, ?it/s]An exception occurred in telemetry logging.Disabling telemetry to prevent further exceptions.
Traceback (most recent call last):
  File "/opt/miniconda3/envs/pialnn/lib/python3.7/site-packages/iopath/common/file_io.py", line 946, in __log_tmetry_keys
    handler.log_event()
  File "/opt/miniconda3/envs/pialnn/lib/python3.7/site-packages/iopath/common/event_logger.py", line 97, in log_event
    del self._evt
AttributeError: _evt
/opt/miniconda3/envs/pialnn/lib/python3.7/site-packages/pytorch3d/io/obj_io.py:530: UserWarning: No mtl file provided
  warnings.warn("No mtl file provided")
 25%|██▌       | 1/4 [00:01<00:04,  1.41s/it]An exception occurred in telemetry logging.Disabling telemetry to prevent further exceptions.
Traceback (most recent call last):
  File "/opt/miniconda3/envs/pialnn/lib/python3.7/site-packages/iopath/common/file_io.py", line 946, in __log_tmetry_keys
    handler.log_event()
  File "/opt/miniconda3/envs/pialnn/lib/python3.7/site-packages/iopath/common/event_logger.py", line 97, in log_event
    del self._evt
AttributeError: _evt
 50%|█████     | 2/4 [00:02<00:02,  1.35s/it]An exception occurred in telemetry logging.Disabling telemetry to prevent further exceptions.
Traceback (most recent call last):
  File "/opt/miniconda3/envs/pialnn/lib/python3.7/site-packages/iopath/common/file_io.py", line 946, in __log_tmetry_keys
    handler.log_event()
  File "/opt/miniconda3/envs/pialnn/lib/python3.7/site-packages/iopath/common/event_logger.py", line 97, in log_event
    del self._evt
AttributeError: _evt
 75%|███████▌  | 3/4 [00:04<00:01,  1.37s/it]An exception occurred in telemetry logging.Disabling telemetry to prevent further exceptions.
Traceback (most recent call last):
  File "/opt/miniconda3/envs/pialnn/lib/python3.7/site-packages/iopath/common/file_io.py", line 946, in __log_tmetry_keys
    handler.log_event()
  File "/opt/miniconda3/envs/pialnn/lib/python3.7/site-packages/iopath/common/event_logger.py", line 97, in log_event
    del self._evt
AttributeError: _evt
100%|██████████| 4/4 [00:05<00:00,  1.35s/it]100%|██████████| 4/4 [00:05<00:00,  1.36s/it]
  0%|          | 0/201 [00:00<?, ?it/s]  0%|          | 0/201 [00:00<?, ?it/s]
Traceback (most recent call last):
  File "train.py", line 104, in <module>
    normal = compute_normal(v_in.unsqueeze(0), f_in.unsqueeze(0))#Todo:remove unsqueeze.
  File "/pialnn/utils.py", line 124, in compute_normal
    faces=list(f)).verts_normals_list()[0]
  File "/opt/miniconda3/envs/pialnn/lib/python3.7/site-packages/pytorch3d/structures/meshes.py", line 345, in __init__
    f[f.gt(-1).all(1)].to(torch.int64) if len(f) > 0 else f for f in faces
  File "/opt/miniconda3/envs/pialnn/lib/python3.7/site-packages/pytorch3d/structures/meshes.py", line 345, in <listcomp>
    f[f.gt(-1).all(1)].to(torch.int64) if len(f) > 0 else f for f in faces
IndexError: The shape of the mask [1, 3] at index 1 does not match the shape of the indexed tensor [1, 80000, 3] at index 1
