  0%|          | 0/4 [00:00<?, ?it/s]An exception occurred in telemetry logging.Disabling telemetry to prevent further exceptions.
Traceback (most recent call last):
  File "/opt/miniconda3/envs/pialnn/lib/python3.7/site-packages/iopath/common/file_io.py", line 946, in __log_tmetry_keys
    handler.log_event()
  File "/opt/miniconda3/envs/pialnn/lib/python3.7/site-packages/iopath/common/event_logger.py", line 97, in log_event
    del self._evt
AttributeError: _evt
/opt/miniconda3/envs/pialnn/lib/python3.7/site-packages/pytorch3d/io/obj_io.py:534: UserWarning: Mtl file does not exist: /pialnn/resources/mods/lh_white_smooth_140k_mod.mtl
  warnings.warn(f"Mtl file does not exist: {f}")
 25%|██▌       | 1/4 [00:03<00:10,  3.62s/it]An exception occurred in telemetry logging.Disabling telemetry to prevent further exceptions.
Traceback (most recent call last):
  File "/opt/miniconda3/envs/pialnn/lib/python3.7/site-packages/iopath/common/file_io.py", line 946, in __log_tmetry_keys
    handler.log_event()
  File "/opt/miniconda3/envs/pialnn/lib/python3.7/site-packages/iopath/common/event_logger.py", line 97, in log_event
    del self._evt
AttributeError: _evt
 50%|█████     | 2/4 [00:07<00:07,  3.55s/it]An exception occurred in telemetry logging.Disabling telemetry to prevent further exceptions.
Traceback (most recent call last):
  File "/opt/miniconda3/envs/pialnn/lib/python3.7/site-packages/iopath/common/file_io.py", line 946, in __log_tmetry_keys
    handler.log_event()
  File "/opt/miniconda3/envs/pialnn/lib/python3.7/site-packages/iopath/common/event_logger.py", line 97, in log_event
    del self._evt
AttributeError: _evt
 75%|███████▌  | 3/4 [00:10<00:03,  3.59s/it]An exception occurred in telemetry logging.Disabling telemetry to prevent further exceptions.
Traceback (most recent call last):
  File "/opt/miniconda3/envs/pialnn/lib/python3.7/site-packages/iopath/common/file_io.py", line 946, in __log_tmetry_keys
    handler.log_event()
  File "/opt/miniconda3/envs/pialnn/lib/python3.7/site-packages/iopath/common/event_logger.py", line 97, in log_event
    del self._evt
AttributeError: _evt
100%|██████████| 4/4 [00:14<00:00,  3.62s/it]100%|██████████| 4/4 [00:14<00:00,  3.61s/it]
  0%|          | 0/201 [00:00<?, ?it/s]  0%|          | 1/201 [00:36<2:01:18, 36.39s/it]  1%|          | 2/201 [01:00<1:36:59, 29.24s/it]  1%|▏         | 3/201 [01:24<1:29:02, 26.98s/it]  2%|▏         | 4/201 [01:49<1:25:08, 25.93s/it]  2%|▏         | 5/201 [02:13<1:22:51, 25.36s/it]  3%|▎         | 6/201 [02:37<1:21:18, 25.02s/it]  3%|▎         | 7/201 [03:02<1:20:14, 24.82s/it]  4%|▍         | 8/201 [03:26<1:19:21, 24.67s/it]slurmstepd: error: *** JOB 3976315 ON arctrdagn009 CANCELLED AT 2023-11-22T21:07:02 ***
