  0%|          | 0/4 [00:00<?, ?it/s]An exception occurred in telemetry logging.Disabling telemetry to prevent further exceptions.
Traceback (most recent call last):
  File "/opt/miniconda3/envs/pialnn/lib/python3.7/site-packages/iopath/common/file_io.py", line 946, in __log_tmetry_keys
    handler.log_event()
  File "/opt/miniconda3/envs/pialnn/lib/python3.7/site-packages/iopath/common/event_logger.py", line 97, in log_event
    del self._evt
AttributeError: _evt
/opt/miniconda3/envs/pialnn/lib/python3.7/site-packages/pytorch3d/io/obj_io.py:534: UserWarning: Mtl file does not exist: /pialnn/resources/mods/lh_white_smooth_140k_mod.mtl
  warnings.warn(f"Mtl file does not exist: {f}")
 25%|██▌       | 1/4 [00:03<00:10,  3.50s/it]An exception occurred in telemetry logging.Disabling telemetry to prevent further exceptions.
Traceback (most recent call last):
  File "/opt/miniconda3/envs/pialnn/lib/python3.7/site-packages/iopath/common/file_io.py", line 946, in __log_tmetry_keys
    handler.log_event()
  File "/opt/miniconda3/envs/pialnn/lib/python3.7/site-packages/iopath/common/event_logger.py", line 97, in log_event
    del self._evt
AttributeError: _evt
 50%|█████     | 2/4 [00:06<00:06,  3.40s/it]An exception occurred in telemetry logging.Disabling telemetry to prevent further exceptions.
Traceback (most recent call last):
  File "/opt/miniconda3/envs/pialnn/lib/python3.7/site-packages/iopath/common/file_io.py", line 946, in __log_tmetry_keys
    handler.log_event()
  File "/opt/miniconda3/envs/pialnn/lib/python3.7/site-packages/iopath/common/event_logger.py", line 97, in log_event
    del self._evt
AttributeError: _evt
 75%|███████▌  | 3/4 [00:10<00:03,  3.38s/it]An exception occurred in telemetry logging.Disabling telemetry to prevent further exceptions.
Traceback (most recent call last):
  File "/opt/miniconda3/envs/pialnn/lib/python3.7/site-packages/iopath/common/file_io.py", line 946, in __log_tmetry_keys
    handler.log_event()
  File "/opt/miniconda3/envs/pialnn/lib/python3.7/site-packages/iopath/common/event_logger.py", line 97, in log_event
    del self._evt
AttributeError: _evt
100%|██████████| 4/4 [00:13<00:00,  3.38s/it]100%|██████████| 4/4 [00:13<00:00,  3.39s/it]
  0%|          | 0/201 [00:00<?, ?it/s]  0%|          | 1/201 [00:36<2:00:07, 36.04s/it]  1%|          | 2/201 [01:00<1:36:38, 29.14s/it]  1%|▏         | 3/201 [01:24<1:29:02, 26.98s/it]  2%|▏         | 4/201 [01:49<1:25:18, 25.98s/it]  2%|▏         | 5/201 [02:13<1:23:03, 25.43s/it]  3%|▎         | 6/201 [02:38<1:21:33, 25.10s/it]  3%|▎         | 7/201 [03:02<1:20:27, 24.89s/it]  4%|▍         | 8/201 [03:27<1:19:36, 24.75s/it]  4%|▍         | 9/201 [03:51<1:18:54, 24.66s/it]  5%|▍         | 10/201 [04:15<1:18:18, 24.60s/it]  5%|▌         | 11/201 [04:49<1:26:08, 27.20s/it]  6%|▌         | 12/201 [05:13<1:23:01, 26.36s/it]  6%|▋         | 13/201 [05:37<1:20:46, 25.78s/it]  7%|▋         | 14/201 [06:02<1:19:06, 25.38s/it]  7%|▋         | 15/201 [06:26<1:17:49, 25.11s/it]  8%|▊         | 16/201 [06:51<1:16:48, 24.91s/it]slurmstepd: error: *** JOB 3976273 ON arctrdagn005 CANCELLED AT 2023-11-22T21:02:46 ***
