  0%|          | 0/4 [00:00<?, ?it/s]An exception occurred in telemetry logging.Disabling telemetry to prevent further exceptions.
Traceback (most recent call last):
  File "/opt/miniconda3/envs/pialnn/lib/python3.7/site-packages/iopath/common/file_io.py", line 946, in __log_tmetry_keys
    handler.log_event()
  File "/opt/miniconda3/envs/pialnn/lib/python3.7/site-packages/iopath/common/event_logger.py", line 97, in log_event
    del self._evt
AttributeError: _evt
/opt/miniconda3/envs/pialnn/lib/python3.7/site-packages/pytorch3d/io/obj_io.py:534: UserWarning: Mtl file does not exist: /pialnn/resources/mods/lh_white_smooth_140k_mod_pial.mtl
  warnings.warn(f"Mtl file does not exist: {f}")
 25%|██▌       | 1/4 [00:03<00:11,  3.78s/it]An exception occurred in telemetry logging.Disabling telemetry to prevent further exceptions.
Traceback (most recent call last):
  File "/opt/miniconda3/envs/pialnn/lib/python3.7/site-packages/iopath/common/file_io.py", line 946, in __log_tmetry_keys
    handler.log_event()
  File "/opt/miniconda3/envs/pialnn/lib/python3.7/site-packages/iopath/common/event_logger.py", line 97, in log_event
    del self._evt
AttributeError: _evt
 50%|█████     | 2/4 [00:07<00:07,  3.71s/it]An exception occurred in telemetry logging.Disabling telemetry to prevent further exceptions.
Traceback (most recent call last):
  File "/opt/miniconda3/envs/pialnn/lib/python3.7/site-packages/iopath/common/file_io.py", line 946, in __log_tmetry_keys
    handler.log_event()
  File "/opt/miniconda3/envs/pialnn/lib/python3.7/site-packages/iopath/common/event_logger.py", line 97, in log_event
    del self._evt
AttributeError: _evt
 75%|███████▌  | 3/4 [00:10<00:03,  3.64s/it]An exception occurred in telemetry logging.Disabling telemetry to prevent further exceptions.
Traceback (most recent call last):
  File "/opt/miniconda3/envs/pialnn/lib/python3.7/site-packages/iopath/common/file_io.py", line 946, in __log_tmetry_keys
    handler.log_event()
  File "/opt/miniconda3/envs/pialnn/lib/python3.7/site-packages/iopath/common/event_logger.py", line 97, in log_event
    del self._evt
AttributeError: _evt
100%|██████████| 4/4 [00:14<00:00,  3.65s/it]100%|██████████| 4/4 [00:14<00:00,  3.66s/it]
  0%|          | 0/201 [00:00<?, ?it/s]  0%|          | 1/201 [00:42<2:22:36, 42.78s/it]  1%|          | 2/201 [01:12<1:56:46, 35.21s/it]  1%|▏         | 3/201 [01:42<1:48:18, 32.82s/it]  2%|▏         | 4/201 [02:12<1:44:09, 31.72s/it]  2%|▏         | 5/201 [02:42<1:41:43, 31.14s/it]  3%|▎         | 6/201 [03:12<1:40:03, 30.79s/it]  3%|▎         | 7/201 [03:43<1:38:50, 30.57s/it]  4%|▍         | 8/201 [04:13<1:37:50, 30.42s/it]  4%|▍         | 9/201 [04:43<1:37:01, 30.32s/it]slurmstepd: error: *** JOB 3978118 ON arctrdagn009 CANCELLED AT 2023-11-23T00:42:49 ***
